Workbook
Name UPDATE: 'Data Sheet'!$E$1

Sheet Profit & Loss
A1: ='Data Sheet'!B1 -> BRITANNIA INDUSTRIES LTD | H1: =UPDATE
A3: Narration | B3: ='Data Sheet'!B16 -> 42825 | C3: ='Data Sheet'!C16 -> 43190 | D3: ='Data Sheet'!D16 -> 43555 | E3: ='Data Sheet'!E16 -> 43921 | F3: ='Data Sheet'!F16 -> 44286 | G3: ='Data Sheet'!G16 -> 44651 | H3: ='Data Sheet'!H16 -> 45016 | I3: ='Data Sheet'!I16 -> 45382 | ... K3: ='Data Sheet'!K16 -> 46112 | L3: 46447 | M3: 46813 | N3: 47178 | O3: 47543 | P3: 47908
A4: Sales | B4: ='Data Sheet'!B17 -> 9054.09 | C4: ='Data Sheet'!C17 -> 9913.99 | D4: ='Data Sheet'!D17 -> 11054.67 | E4: ='Data Sheet'!E17 -> 11599.55 | F4: ='Data Sheet'!F17 -> 13136.14 | G4: ='Data Sheet'!G17 -> 14136.26 | H4: ='Data Sheet'!H17 -> 16300.55 | I4: ='Data Sheet'!I17 -> 16769.27 | ... K4: ='Data Sheet'!K17 -> 19151.59 | L4: =K4*(1+assumption!$B$1) -> 20573.773 | M4: =L4*(1+assumption!$B$1) -> 22101.565 | N4: =M4*(1+assumption!$B$1) -> 23742.811 | O4: =N4*(1+assumption!$B$1) -> 25505.934 | P4: =O4*(1+assumption!$B$1) -> 27399.985
A5: Expenses | B5: =SUM('Data Sheet'!B18,'Data Sheet'!B20:B24, -1*'Data Sheet'!B19) -> 7775.91 | C5: =SUM('Data Sheet'!C18,'Data Sheet'!C20:C24, -1*'Data Sheet'!C19) -> 8412.52 | D5: =SUM('Data Sheet'!D18,'Data Sheet'!D20:D24, -1*'Data Sheet'!D19) -> 9322.22 | E5: =SUM('Data Sheet'!E18,'Data Sheet'!E20:E24, -1*'Data Sheet'!E19) -> 9756.37 | F5: =SUM('Data Sheet'!F18,'Data Sheet'!F20:F24, -1*'Data Sheet'!F19) -> 10626.85 | G5: =SUM('Data Sheet'!G18,'Data Sheet'!G20:G24, -1*'Data Sheet'!G19) -> 11934.95 | H5: =SUM('Data Sheet'!H18,'Data Sheet'!H20:H24, -1*'Data Sheet'!H19) -> 13469.64 | I5: =SUM('Data Sheet'!I18,'Data Sheet'!I20:I24, -1*'Data Sheet'!I19) -> 13602.62 | ... K5: =SUM('Data Sheet'!K18,'Data Sheet'!K20:K24, -1*'Data Sheet'!K19) -> 15637.25 | L5: =L4-L6 -> 16798.46 | M5: =M4-M6 -> 18045.901 | N5: =N4-N6 -> 19385.976 | O5: =O4-O6 -> 20825.564 | P5: =P4-P6 -> 22372.055
A6: Operating Profit | B6: =B4-B5 -> 1278.18 | C6: =C4-C5 -> 1501.47 | D6: =D4-D5 -> 1732.45 | E6: =E4-E5 -> 1843.18 | F6: =F4-F5 -> 2509.29 | G6: =G4-G5 -> 2201.31 | H6: =H4-H5 -> 2830.91 | I6: =I4-I5 -> 3166.65 | ... K6: =K4-K5 -> 3514.34 | L6: =L4*assumption!$B$2 -> 3775.3122 | M6: =M4*assumption!$B$2 -> 4055.6641 | N6: =N4*assumption!$B$2 -> 4356.8346 | O6: =O4*assumption!$B$2 -> 4680.3698 | P6: =P4*assumption!$B$2 -> 5027.9306
A7: Other Income | B7: ='Data Sheet'!B25 -> 150.54 | C7: ='Data Sheet'!C25 -> 166.37 | D7: ='Data Sheet'!D25 -> 206.45 | E7: ='Data Sheet'!E25 -> 262.83 | F7: ='Data Sheet'!F25 -> 313.07 | G7: ='Data Sheet'!G25 -> 221.85 | H7: ='Data Sheet'!H25 -> 596.87 | I7: ='Data Sheet'!I25 -> 211.28 | ... K7: ='Data Sheet'!K25 -> 224.03 | L7: =AVERAGE(I7:K7) -> 212.53667 | M7: =AVERAGE(J7:L7) -> 212.95556 | N7: =AVERAGE(K7:M7) -> 216.50741 | O7: =AVERAGE(L7:N7) -> 213.99988 | P7: =AVERAGE(M7:O7) -> 214.48761
A8: Depreciation | B8: ='Data Sheet'!B26 -> 119.27 | C8: ='Data Sheet'!C26 -> 142.07 | D8: ='Data Sheet'!D26 -> 161.88 | E8: ='Data Sheet'!E26 -> 184.81 | F8: ='Data Sheet'!F26 -> 197.85 | G8: ='Data Sheet'!G26 -> 200.54 | H8: ='Data Sheet'!H26 -> 225.91 | I8: ='Data Sheet'!I26 -> 300.46 | ... K8: ='Data Sheet'!K26 -> 336.83 | L8: =('Balance Sheet'!K10+'Balance Sheet'!K11)*assumption!$B$4 -> 317.7856 | M8: =('Balance Sheet'!L10+'Balance Sheet'!L11)*assumption!$B$4 -> 350.72263 | N8: =('Balance Sheet'!M10+'Balance Sheet'!M11)*assumption!$B$4 -> 385.07831 | O8: =('Balance Sheet'!N10+'Balance Sheet'!N11)*assumption!$B$4 -> 421.07097 | P8: =('Balance Sheet'!O10+'Balance Sheet'!O11)*assumption!$B$4 -> 458.92275
A9: Interest | B9: ='Data Sheet'!B27 -> 5.45 | C9: ='Data Sheet'!C27 -> 7.59 | D9: ='Data Sheet'!D27 -> 9.09 | E9: ='Data Sheet'!E27 -> 76.9 | F9: ='Data Sheet'!F27 -> 110.9 | G9: ='Data Sheet'!G27 -> 144.29 | H9: ='Data Sheet'!H27 -> 169.1 | I9: ='Data Sheet'!I27 -> 164 | ... K9: ='Data Sheet'!K27 -> 112.76 | L9: ='Balance Sheet'!L6*assumption!$B$6 -> 124.2252 | M9: ='Balance Sheet'!M6*assumption!$B$6 -> 124.2252 | N9: ='Balance Sheet'!N6*assumption!$B$6 -> 124.2252 | O9: ='Balance Sheet'!O6*assumption!$B$6 -> 124.2252 | P9: ='Balance Sheet'!P6*assumption!$B$6 -> 124.2252
A10: Profit before tax | B10: ='Data Sheet'!B28 -> 1304 | C10: ='Data Sheet'!C28 -> 1518.18 | D10: ='Data Sheet'!D28 -> 1767.93 | E10: ='Data Sheet'!E28 -> 1844.3 | F10: ='Data Sheet'!F28 -> 2513.61 | G10: ='Data Sheet'!G28 -> 2078.33 | H10: ='Data Sheet'!H28 -> 3032.77 | I10: ='Data Sheet'!I28 -> 2913.47 | ... K10: ='Data Sheet'!K28 -> 3288.78 | L10: =L6+L7-L8-L9 -> 3545.8381 | M10: =M6+M7-M8-M9 -> 3793.6718 | N10: =N6+N7-N8-N9 -> 4064.0385 | O10: =O6+O7-O8-O9 -> 4349.0735 | P10: =P6+P7-P8-P9 -> 4659.2702
A11: Tax | B11: ='Data Sheet'!B29 -> 419.67 | C11: ='Data Sheet'!C29 -> 514.22 | D11: ='Data Sheet'!D29 -> 612.47 | E11: ='Data Sheet'!E29 -> 450.7 | F11: ='Data Sheet'!F29 -> 663.02 | G11: ='Data Sheet'!G29 -> 562.35 | H11: ='Data Sheet'!H29 -> 716.45 | I11: ='Data Sheet'!I29 -> 779.25 | ... K11: ='Data Sheet'!K29 -> 751.77 | L11: =L10*assumption!$B$3 -> 851.00114 | M11: =M10*assumption!$B$3 -> 910.48123 | N11: =N10*assumption!$B$3 -> 975.36924 | O11: =O10*assumption!$B$3 -> 1043.7777 | P11: =P10*assumption!$B$3 -> 1118.2249
A12: Net profit | B12: ='Data Sheet'!B30 -> 884.47 | C12: ='Data Sheet'!C30 -> 1004.23 | D12: ='Data Sheet'!D30 -> 1159.12 | E12: ='Data Sheet'!E30 -> 1402.63 | F12: ='Data Sheet'!F30 -> 1863.9 | G12: ='Data Sheet'!G30 -> 1524.82 | H12: ='Data Sheet'!H30 -> 2321.77 | I12: ='Data Sheet'!I30 -> 2139.81 | ... K12: ='Data Sheet'!K30 -> 2533.49 | L12: =L10-L11 -> 2694.837 | M12: =M10-M11 -> 2883.1906 | N12: =N10-N11 -> 3088.6693 | O12: =O10-O11 -> 3305.2959 | P12: =P10-P11 -> 3541.0454
A13: EPS | B13: =IF('Data Sheet'!B93>0,B12/'Data Sheet'!B93,0) -> 36.852917 | C13: =IF('Data Sheet'!C93>0,C12/'Data Sheet'!C93,0) -> 41.825489 | D13: =IF('Data Sheet'!D93>0,D12/'Data Sheet'!D93,0) -> 48.236371 | E13: =IF('Data Sheet'!E93>0,E12/'Data Sheet'!E93,0) -> 58.321414 | F13: =IF('Data Sheet'!F93>0,F12/'Data Sheet'!F93,0) -> 77.372354 | G13: =IF('Data Sheet'!G93>0,G12/'Data Sheet'!G93,0) -> 63.296804 | H13: =IF('Data Sheet'!H93>0,H12/'Data Sheet'!H93,0) -> 96.378995 | I13: =IF('Data Sheet'!I93>0,I12/'Data Sheet'!I93,0) -> 88.825654 | ... K13: =IF('Data Sheet'!K93>0,K12/'Data Sheet'!K93,0) -> 105.1677 | L13: =L12/'Data Sheet'!$K$93 -> 111.86538 | M13: =M12/'Data Sheet'!$K$93 -> 119.68412 | N13: =N12/'Data Sheet'!$K$93 -> 128.21375 | O13: =O12/'Data Sheet'!$K$93 -> 137.20614 | P13: =P12/'Data Sheet'!$K$93 -> 146.99234
A14: Price to earning | B14: =IF(B15>0,B15/B13,"") -> 45.776567 | C14: =IF(C15>0,C15/C13,"") -> 59.420703 | D14: =IF(D15>0,D15/D13,"") -> 63.966255 | E14: =IF(E15>0,E15/E13,"") -> 46.105707 | F14: =IF(F15>0,F15/F13,"") -> 46.852006 | G14: =IF(G15>0,G15/G13,"") -> 50.656586 | H14: =IF(H15>0,H15/H13,"") -> 44.845352 | I14: =IF(I15>0,I15/I13,"") -> 55.290896 | ... K14: =IF(K15>0,K15/K13,"") -> 51.56526
A15: Price | B15: ='Data Sheet'!B90 -> 1687 | C15: ='Data Sheet'!C90 -> 2485.3 | D15: ='Data Sheet'!D90 -> 3085.5 | E15: ='Data Sheet'!E90 -> 2688.95 | F15: ='Data Sheet'!F90 -> 3625.05 | G15: ='Data Sheet'!G90 -> 3206.4 | H15: ='Data Sheet'!H90 -> 4322.15 | I15: ='Data Sheet'!I90 -> 4911.25 | ... K15: ='Data Sheet'!K90 -> 5423
A17: RATIOS:
A18: Dividend Payout | B18: =IF('Data Sheet'!B30>0, 'Data Sheet'!B31/'Data Sheet'!B30, 0) -> 0.29848384 | C18: =IF('Data Sheet'!C30>0, 'Data Sheet'!C31/'Data Sheet'!C30, 0) -> 0.29885584 | D18: =IF('Data Sheet'!D30>0, 'Data Sheet'!D31/'Data Sheet'!D30, 0) -> 0.31096867 | E18: =IF('Data Sheet'!E30>0, 'Data Sheet'!E31/'Data Sheet'!E30, 0) -> 0.60012263 | F18: =IF('Data Sheet'!F30>0, 'Data Sheet'!F31/'Data Sheet'!F30, 0) -> 2.0356135 | G18: =IF('Data Sheet'!G30>0, 'Data Sheet'!G31/'Data Sheet'!G30, 0) -> 0.89261683 | H18: =IF('Data Sheet'!H30>0, 'Data Sheet'!H31/'Data Sheet'!H30, 0) -> 0.74705074 | I18: =IF('Data Sheet'!I30>0, 'Data Sheet'!I31/'Data Sheet'!I30, 0) -> 0.82746599 | ... K18: =IF('Data Sheet'!K30>0, 'Data Sheet'!K31/'Data Sheet'!K30, 0) -> 0.86052836
A19: OPM | B19: =IF(B6>0,B6/B4,0) -> 0.14117156 | C19: =IF(C6>0,C6/C4,0) -> 0.15144962 | D19: =IF(D6>0,D6/D4,0) -> 0.15671657 | E19: =IF(E6>0,E6/E4,0) -> 0.15890099 | F19: =IF(F6>0,F6/F4,0) -> 0.19102187 | G19: =IF(G6>0,G6/G4,0) -> 0.15572082 | H19: =IF(H6>0,H6/H4,0) -> 0.1736696 | I19: =IF(I6>0,I6/I4,0) -> 0.18883648 | ... P19: =IF(P6>0,P6/P4,0) -> 0.18350121
G22: TRENDS: | H22: 10 YEARS | I22: 7 YEARS | J22: 5 YEARS | K22: 3 YEARS
G23: Sales Growth | H23: =IF(B4=0,"",POWER($K4/B4,1/10)-1) -> 0.077794599 | I23: =IF(D4=0,"",POWER($K4/D4,1/7)-1) -> 0.08166842 | J23: =IF(F4=0,"",POWER($K4/F4,1/5)-1) -> 0.078319387 | K23: =IF(H4=0,"",POWER($K4/H4, 1/3)-1) -> 0.055198566
G24: OPM | H24: =IF(SUM(B4:$K$4)=0,"",SUMPRODUCT(B19:$K$19,B4:$K$4)/SUM(B4:$K$4)) -> 0.17082122 | I24: =IF(SUM(E4:$K$4)=0,"",SUMPRODUCT(E19:$K$19,E4:$K$4)/SUM(E4:$K$4)) -> 0.1764746 | J24: =IF(SUM(G4:$K$4)=0,"",SUMPRODUCT(G19:$K$19,G4:$K$4)/SUM(G4:$K$4)) -> 0.17662586 | K24: =IF(SUM(I4:$K$4)=0, "", SUMPRODUCT(I19:$K$19,I4:$K$4)/SUM(I4:$K$4)) -> 0.18300694
G25: Price to Earning | H25: =IF(ISERROR(AVERAGEIF(B14:$L14,">0")),"",AVERAGEIF(B14:$L14,">0")) -> 51.906614 | I25: =IF(ISERROR(AVERAGEIF(E14:$L14,">0")),"",AVERAGEIF(E14:$L14,">0")) -> 49.986088 | J25: =IF(ISERROR(AVERAGEIF(G14:$L14,">0")),"",AVERAGEIF(G14:$L14,">0")) -> 51.388981 | K25: =IF(ISERROR(AVERAGEIF(I14:$L14,">0")),"",AVERAGEIF(I14:$L14,">0")) -> 53.814322
H33: =(K4/E4)^(1/7)-1 -> 0.074259243
H34: =(K5/E5)^(1/7)-1 -> 0.069713423

Sheet Balance Sheet
A1: ='Profit & Loss'!A1 -> BRITANNIA INDUSTRIES LTD | E1: =UPDATE | J1: SCREENER.IN
A3: Narration | B3: ='Data Sheet'!B56 -> 42825 | C3: ='Data Sheet'!C56 -> 43190 | D3: ='Data Sheet'!D56 -> 43555 | E3: ='Data Sheet'!E56 -> 43921 | F3: ='Data Sheet'!F56 -> 44286 | G3: ='Data Sheet'!G56 -> 44651 | H3: ='Data Sheet'!H56 -> 45016 | I3: ='Data Sheet'!I56 -> 45382 | ... K3: ='Data Sheet'!K56 -> 46112 | L3: 46447 | M3: 46813 | N3: 47178 | O3: 47543 | P3: 47908
A4: Equity Share Capital | B4: ='Data Sheet'!B57 -> 24 | C4: ='Data Sheet'!C57 -> 24.01 | D4: ='Data Sheet'!D57 -> 24.03 | E4: ='Data Sheet'!E57 -> 24.05 | F4: ='Data Sheet'!F57 -> 24.09 | G4: ='Data Sheet'!G57 -> 24.09 | H4: ='Data Sheet'!H57 -> 24.09 | I4: ='Data Sheet'!I57 -> 24.09 | ... K4: ='Data Sheet'!K57 -> 24.09 | L4: 24 | M4: 24 | N4: 24 | O4: 24 | P4: 24
A5: Reserves | B5: ='Data Sheet'!B58 -> 2672.42 | C5: ='Data Sheet'!C58 -> 3382.22 | D5: ='Data Sheet'!D58 -> 4229.22 | E5: ='Data Sheet'!E58 -> 4378.78 | F5: ='Data Sheet'!F58 -> 3523.57 | G5: ='Data Sheet'!G58 -> 2534.01 | H5: ='Data Sheet'!H58 -> 3510.18 | I5: ='Data Sheet'!I58 -> 3917.43 | ... K5: ='Data Sheet'!K58 -> 5082.47 | L5: =K5+'Profit & Loss'!L12*(1-assumption!$B$8) -> 5540.5923 | M5: =L5+'Profit & Loss'!M12*(1-assumption!$B$8) -> 6030.7347 | N5: =M5+'Profit & Loss'!N12*(1-assumption!$B$8) -> 6555.8085 | O5: =N5+'Profit & Loss'!O12*(1-assumption!$B$8) -> 7117.7088 | P5: =O5+'Profit & Loss'!P12*(1-assumption!$B$8) -> 7719.6865
A6: Borrowings | B6: ='Data Sheet'!B59 -> 124.56 | C6: ='Data Sheet'!C59 -> 200.7 | D6: ='Data Sheet'!D59 -> 156.02 | E6: ='Data Sheet'!E59 -> 1537.59 | F6: ='Data Sheet'!F59 -> 2106.94 | G6: ='Data Sheet'!G59 -> 2481.2 | H6: ='Data Sheet'!H59 -> 2997.37 | I6: ='Data Sheet'!I59 -> 2064.96 | ... K6: ='Data Sheet'!K59 -> 1380.28 | L6: =K6 -> 1380.28 | M6: =L6 -> 1380.28 | N6: =M6 -> 1380.28 | O6: =N6 -> 1380.28 | P6: =O6 -> 1380.28
A7: Other Liabilities | B7: ='Data Sheet'!B60 -> 1287.82 | C7: ='Data Sheet'!C60 -> 1580.99 | D7: ='Data Sheet'!D60 -> 1828.68 | E7: ='Data Sheet'!E60 -> 1889.12 | F7: ='Data Sheet'!F60 -> 2345.49 | G7: ='Data Sheet'!G60 -> 2487.3 | H7: ='Data Sheet'!H60 -> 2819.21 | I7: ='Data Sheet'!I60 -> 3065.02 | ... K7: ='Data Sheet'!K60 -> 3243.48 | L7: =K7 -> 3243.48 | M7: =L7 -> 3243.48 | N7: =M7 -> 3243.48 | O7: =N7 -> 3243.48 | P7: =O7 -> 3243.48
A8: Total | B8: ='Data Sheet'!B61 -> 4108.8 | C8: ='Data Sheet'!C61 -> 5187.92 | D8: ='Data Sheet'!D61 -> 6237.95 | E8: ='Data Sheet'!E61 -> 7829.54 | F8: ='Data Sheet'!F61 -> 8000.09 | G8: ='Data Sheet'!G61 -> 7526.6 | H8: ='Data Sheet'!H61 -> 9350.85 | I8: ='Data Sheet'!I61 -> 9071.5 | ... K8: ='Data Sheet'!K61 -> 9730.32 | L8: =SUM(L4:L7) -> 10188.352 | M8: =SUM(M4:M7) -> 10678.495 | N8: =SUM(N4:N7) -> 11203.568 | O8: =SUM(O4:O7) -> 11765.469 | P8: =SUM(P4:P7) -> 12367.446
A10: Net Block | B10: ='Data Sheet'!B62 -> 1159.99 | C10: ='Data Sheet'!C62 -> 1345.6 | D10: ='Data Sheet'!D62 -> 1688.3 | E10: ='Data Sheet'!E62 -> 1878.18 | F10: ='Data Sheet'!F62 -> 1792.95 | G10: ='Data Sheet'!G62 -> 1753.21 | H10: ='Data Sheet'!H62 -> 2655.22 | I10: ='Data Sheet'!I62 -> 2771.14 | ... K10: ='Data Sheet'!K62 -> 2849.92 | L10: =K10+'Profit & Loss'!L4*assumption!$B$5-'Profit & Loss'!L8 -> 3149.3476 | M10: =L10+'Profit & Loss'!M4*assumption!$B$5-'Profit & Loss'!M8 -> 3461.6719 | N10: =M10+'Profit & Loss'!N4*assumption!$B$5-'Profit & Loss'!N8 -> 3788.8779 | O10: =N10+'Profit & Loss'!O4*assumption!$B$5-'Profit & Loss'!O8 -> 4132.985 | P10: =O10+'Profit & Loss'!P4*assumption!$B$5-'Profit & Loss'!P8 -> 4496.0618
A11: Capital Work in Progress | B11: ='Data Sheet'!B63 -> 30.07 | C11: ='Data Sheet'!C63 -> 202.82 | D11: ='Data Sheet'!D63 -> 101.24 | E11: ='Data Sheet'!E63 -> 39.55 | F11: ='Data Sheet'!F63 -> 116.52 | G11: ='Data Sheet'!G63 -> 535.68 | H11: ='Data Sheet'!H63 -> 105 | I11: ='Data Sheet'!I63 -> 187.54 | ... K11: ='Data Sheet'!K63 -> 39.04 | L11: =K11 -> 39.04 | M11: =L11 -> 39.04 | N11: =M11 -> 39.04 | O11: =N11 -> 39.04 | P11: =O11 -> 39.04
A12: Investments | B12: ='Data Sheet'!B64 -> 486.85 | C12: ='Data Sheet'!C64 -> 1079.28 | D12: ='Data Sheet'!D64 -> 1476.28 | E12: ='Data Sheet'!E64 -> 2893.23 | F12: ='Data Sheet'!F64 -> 2780.69 | G12: ='Data Sheet'!G64 -> 1762.37 | H12: ='Data Sheet'!H64 -> 3324.24 | I12: ='Data Sheet'!I64 -> 2766.72 | ... K12: ='Data Sheet'!K64 -> 3609.76 | L12: =K12 -> 3609.76 | M12: =L12 -> 3609.76 | N12: =M12 -> 3609.76 | O12: =N12 -> 3609.76 | P12: =O12 -> 3609.76
A13: Other Assets | B13: ='Data Sheet'!B65 -> 2431.89 | C13: ='Data Sheet'!C65 -> 2560.22 | D13: ='Data Sheet'!D65 -> 2972.13 | E13: ='Data Sheet'!E65 -> 3018.58 | F13: ='Data Sheet'!F65 -> 3309.93 | G13: ='Data Sheet'!G65 -> 3475.34 | H13: ='Data Sheet'!H65 -> 3266.39 | I13: ='Data Sheet'!I65 -> 3346.1 | ... K13: ='Data Sheet'!K65 -> 3231.6 | L13: =L8-L10-L11-L12 -> 3390.2047 | M13: =M8-M10-M11-M12 -> 3568.0228 | N13: =N8-N10-N11-N12 -> 3765.8905 | O13: =O8-O10-O11-O12 -> 3983.6838 | P13: =P8-P10-P11-P12 -> 4222.5847
A14: Total | B14: ='Data Sheet'!B66 -> 4108.8 | C14: ='Data Sheet'!C66 -> 5187.92 | D14: ='Data Sheet'!D66 -> 6237.95 | E14: ='Data Sheet'!E66 -> 7829.54 | F14: ='Data Sheet'!F66 -> 8000.09 | G14: ='Data Sheet'!G66 -> 7526.6 | H14: ='Data Sheet'!H66 -> 9350.85 | I14: ='Data Sheet'!I66 -> 9071.5 | ... K14: ='Data Sheet'!K66 -> 9730.32 | L14: =SUM(L10:L13) -> 10188.352 | M14: =SUM(M10:M13) -> 10678.495 | N14: =SUM(N10:N13) -> 11203.568 | O14: =SUM(O10:O13) -> 11765.469 | P14: =SUM(P10:P13) -> 12367.446
A16: Working Capital | B16: =B13-B7 -> 1144.07 | C16: =C13-C7 -> 979.23 | D16: =D13-D7 -> 1143.45 | E16: =E13-E7 -> 1129.46 | F16: =F13-F7 -> 964.44 | G16: =G13-G7 -> 988.04 | H16: =H13-H7 -> 447.18 | I16: =I13-I7 -> 281.08 | ... P16: =P13-P7 -> 979.10468
A17: Debtors | B17: ='Data Sheet'!B67 -> 179.16 | C17: ='Data Sheet'!C67 -> 304.6 | D17: ='Data Sheet'!D67 -> 394.24 | E17: ='Data Sheet'!E67 -> 320.36 | F17: ='Data Sheet'!F67 -> 257.27 | G17: ='Data Sheet'!G67 -> 331.93 | H17: ='Data Sheet'!H67 -> 328.94 | I17: ='Data Sheet'!I67 -> 393.33 | ... K17: ='Data Sheet'!K67 -> 469.21 | L17: =AVERAGE(I17:K17) -> 437.05 | M17: =AVERAGE(J17:L17) -> 451.62333 | N17: =AVERAGE(K17:M17) -> 452.62778 | O17: =AVERAGE(L17:N17) -> 447.10037 | P17: =AVERAGE(M17:O17) -> 450.45049
A18: Inventory | B18: ='Data Sheet'!B68 -> 661.45 | C18: ='Data Sheet'!C68 -> 652.79 | D18: ='Data Sheet'!D68 -> 781.38 | E18: ='Data Sheet'!E68 -> 740.96 | F18: ='Data Sheet'!F68 -> 1091.49 | G18: ='Data Sheet'!G68 -> 1367.49 | H18: ='Data Sheet'!H68 -> 1193.26 | I18: ='Data Sheet'!I68 -> 1181.22 | ... K18: ='Data Sheet'!K68 -> 1345.93 | L18: =AVERAGE(I18:K18) -> 1254.5533 | M18: =AVERAGE(J18:L18) -> 1278.9978 | N18: =AVERAGE(K18:M18) -> 1293.1604 | O18: =AVERAGE(L18:N18) -> 1275.5705 | P18: =AVERAGE(M18:O18) -> 1282.5762
A20: Debtor Days | B20: =IF('Profit & Loss'!B4>0,'Balance Sheet'!B17/('Profit & Loss'!B4/365),0) -> 7.222526 | C20: =IF('Profit & Loss'!C4>0,'Balance Sheet'!C17/('Profit & Loss'!C4/365),0) -> 11.214355 | D20: =IF('Profit & Loss'!D4>0,'Balance Sheet'!D17/('Profit & Loss'!D4/365),0) -> 13.016906 | E20: =IF('Profit & Loss'!E4>0,'Balance Sheet'!E17/('Profit & Loss'!E4/365),0) -> 10.080684 | F20: =IF('Profit & Loss'!F4>0,'Balance Sheet'!F17/('Profit & Loss'!F4/365),0) -> 7.1484888 | G20: =IF('Profit & Loss'!G4>0,'Balance Sheet'!G17/('Profit & Loss'!G4/365),0) -> 8.5704741 | H20: =IF('Profit & Loss'!H4>0,'Balance Sheet'!H17/('Profit & Loss'!H4/365),0) -> 7.3655858 | I20: =IF('Profit & Loss'!I4>0,'Balance Sheet'!I17/('Profit & Loss'!I4/365),0) -> 8.5612224 | ... P20: =IF('Profit & Loss'!P4>0,'Balance Sheet'!P17/('Profit & Loss'!P4/365),0) -> 6.0005298
A21: Inventory Turnover | B21: =IF('Balance Sheet'!B18>0,'Profit & Loss'!B4/'Balance Sheet'!B18,0) -> 13.688246 | C21: =IF('Balance Sheet'!C18>0,'Profit & Loss'!C4/'Balance Sheet'!C18,0) -> 15.187105 | D21: =IF('Balance Sheet'!D18>0,'Profit & Loss'!D4/'Balance Sheet'!D18,0) -> 14.147623 | E21: =IF('Balance Sheet'!E18>0,'Profit & Loss'!E4/'Balance Sheet'!E18,0) -> 15.654759 | F21: =IF('Balance Sheet'!F18>0,'Profit & Loss'!F4/'Balance Sheet'!F18,0) -> 12.035053 | G21: =IF('Balance Sheet'!G18>0,'Profit & Loss'!G4/'Balance Sheet'!G18,0) -> 10.337377 | H21: =IF('Balance Sheet'!H18>0,'Profit & Loss'!H4/'Balance Sheet'!H18,0) -> 13.660518 | I21: =IF('Balance Sheet'!I18>0,'Profit & Loss'!I4/'Balance Sheet'!I18,0) -> 14.196568 | ... P21: =IF('Balance Sheet'!P18>0,'Profit & Loss'!P4/'Balance Sheet'!P18,0) -> 21.363242
A23: Return on Equity | B23: =IF(SUM('Balance Sheet'!B4:B5)>0,'Profit & Loss'!B12/SUM('Balance Sheet'!B4:B5),"") -> 0.32801641 | C23: =IF(SUM('Balance Sheet'!C4:C5)>0,'Profit & Loss'!C12/SUM('Balance Sheet'!C4:C5),"") -> 0.29482155 | D23: =IF(SUM('Balance Sheet'!D4:D5)>0,'Profit & Loss'!D12/SUM('Balance Sheet'!D4:D5),"") -> 0.27252572 | E23: =IF(SUM('Balance Sheet'!E4:E5)>0,'Profit & Loss'!E12/SUM('Balance Sheet'!E4:E5),"") -> 0.31857464 | F23: =IF(SUM('Balance Sheet'!F4:F5)>0,'Profit & Loss'!F12/SUM('Balance Sheet'!F4:F5),"") -> 0.52538857 | G23: =IF(SUM('Balance Sheet'!G4:G5)>0,'Profit & Loss'!G12/SUM('Balance Sheet'!G4:G5),"") -> 0.59607521 | H23: =IF(SUM('Balance Sheet'!H4:H5)>0,'Profit & Loss'!H12/SUM('Balance Sheet'!H4:H5),"") -> 0.65693057 | I23: =IF(SUM('Balance Sheet'!I4:I5)>0,'Profit & Loss'!I12/SUM('Balance Sheet'!I4:I5),"") -> 0.54288955 | ... L23: =IF(SUM('Balance Sheet'!L4:L5)>0,'Profit & Loss'!L12/SUM('Balance Sheet'!L4:L5),"") -> 0.48428291 | M23: ='Profit & Loss'!M12/SUM('Balance Sheet'!M4:M5) -> 0.47618776 | N23: =IF(SUM('Balance Sheet'!N4:N5)>0,'Profit & Loss'!N12/SUM('Balance Sheet'!N4:N5),"") -> 0.46941629 | O23: =IF(SUM('Balance Sheet'!O4:O5)>0,'Profit & Loss'!O12/SUM('Balance Sheet'!O4:O5),"") -> 0.46281583 | P23: =IF(SUM('Balance Sheet'!P4:P5)>0,'Profit & Loss'!P12/SUM('Balance Sheet'!P4:P5),"") -> 0.45728161
A24: Return on Capital Emp | C24: =IF((B4+B5+B6+C4+C5+C6)>0,('Profit & Loss'!C10+'Profit & Loss'!C9)*2/(B4+B5+B6+C4+C5+C6),"") -> 0.47473284 | D24: =IF((C4+C5+C6+D4+D5+D6)>0,('Profit & Loss'!D10+'Profit & Loss'!D9)*2/(C4+C5+C6+D4+D5+D6),"") -> 0.4433572 | E24: =IF((D4+D5+D6+E4+E5+E6)>0,('Profit & Loss'!E10+'Profit & Loss'!E9)*2/(D4+D5+D6+E4+E5+E6),"") -> 0.3712575 | F24: =IF((E4+E5+E6+F4+F5+F6)>0,('Profit & Loss'!F10+'Profit & Loss'!F9)*2/(E4+E5+E6+F4+F5+F6),"") -> 0.45269607 | G24: =IF((F4+F5+F6+G4+G5+G6)>0,('Profit & Loss'!G10+'Profit & Loss'!G9)*2/(F4+F5+F6+G4+G5+G6),"") -> 0.41567997 | H24: =IF((G4+G5+G6+H4+H5+H6)>0,('Profit & Loss'!H10+'Profit & Loss'!H9)*2/(G4+G5+G6+H4+H5+H6),"") -> 0.553433 | I24: =IF((H4+H5+H6+I4+I5+I6)>0,('Profit & Loss'!I10+'Profit & Loss'!I9)*2/(H4+H5+H6+I4+I5+I6),"") -> 0.49089816 | J24: =IF((I4+I5+I6+J4+J5+J6)>0,('Profit & Loss'!J10+'Profit & Loss'!J9)*2/(I4+I5+I6+J4+J5+J6),"") -> 0.52811553 | ... P24: =IF((O4+O5+O6+P4+P5+P6)>0,('Profit & Loss'!P10+'Profit & Loss'!P9)*2/(O4+O5+O6+P4+P5+P6),"") -> 0.54216339

Sheet Cash Flow
A1: ='Balance Sheet'!A1 -> BRITANNIA INDUSTRIES LTD | E1: =UPDATE | J1: SCREENER.IN
A3: Narration | B3: ='Data Sheet'!B81 -> 42825 | C3: ='Data Sheet'!C81 -> 43190 | D3: ='Data Sheet'!D81 -> 43555 | E3: ='Data Sheet'!E81 -> 43921 | F3: ='Data Sheet'!F81 -> 44286 | G3: ='Data Sheet'!G81 -> 44651 | H3: ='Data Sheet'!H81 -> 45016 | I3: ='Data Sheet'!I81 -> 45382 | ... K3: ='Data Sheet'!K81 -> 46112 | L3: 46447 | M3: 46813 | N3: 47178 | O3: 47543 | P3: 47908
A4: Cash from Operating Activity | B4: ='Data Sheet'!B82 -> 441.28 | C4: ='Data Sheet'!C82 -> 1248.77 | D4: ='Data Sheet'!D82 -> 1155.78 | E4: ='Data Sheet'!E82 -> 1484.53 | F4: ='Data Sheet'!F82 -> 1851.07 | G4: ='Data Sheet'!G82 -> 1299.52 | H4: ='Data Sheet'!H82 -> 2526.21 | I4: ='Data Sheet'!I82 -> 2572.98 | ... K4: ='Data Sheet'!K82 -> 2611.6 | L4: ='Profit & Loss'!L12+'Profit & Loss'!L8+('Balance Sheet'!K16-'Balance Sheet'!L16) -> 2854.0178 | M4: ='Profit & Loss'!M12+'Profit & Loss'!M8+('Balance Sheet'!L16-'Balance Sheet'!M16) -> 3056.0951 | N4: ='Profit & Loss'!N12+'Profit & Loss'!N8+('Balance Sheet'!M16-'Balance Sheet'!N16) -> 3275.8798 | O4: ='Profit & Loss'!O12+'Profit & Loss'!O8+('Balance Sheet'!N16-'Balance Sheet'!O16) -> 3508.5736 | P4: ='Profit & Loss'!P12+'Profit & Loss'!P8+('Balance Sheet'!O16-'Balance Sheet'!P16) -> 3761.0672
A5: Cash from Investing Activity | B5: ='Data Sheet'!B83 -> -149.85 | C5: ='Data Sheet'!C83 -> -956.52 | D5: ='Data Sheet'!D83 -> -852.22 | E5: ='Data Sheet'!E83 -> -1525.93 | F5: ='Data Sheet'!F83 -> 458.82 | G5: ='Data Sheet'!G83 -> 914.19 | H5: ='Data Sheet'!H83 -> -1507 | I5: ='Data Sheet'!I83 -> 485.44 | ... K5: ='Data Sheet'!K83 -> -741.38 | L5: =-'Profit & Loss'!L4*assumption!$B$5 -> -617.21318 | M5: =-'Profit & Loss'!M4*assumption!$B$5 -> -663.04696 | N5: =-'Profit & Loss'!N4*assumption!$B$5 -> -712.28433 | O5: =-'Profit & Loss'!O4*assumption!$B$5 -> -765.17802 | P5: =-'Profit & Loss'!P4*assumption!$B$5 -> -821.99956
A6: Cash from Financing Activity | B6: ='Data Sheet'!B84 -> -295.08 | C6: ='Data Sheet'!C84 -> -231.75 | D6: ='Data Sheet'!D84 -> -352.68 | E6: ='Data Sheet'!E84 -> 57.94 | F6: ='Data Sheet'!F84 -> -2243.69 | G6: ='Data Sheet'!G84 -> -2245.84 | H6: ='Data Sheet'!H84 -> -1028.37 | I6: ='Data Sheet'!I84 -> -2839.13 | ... K6: ='Data Sheet'!K84 -> -1782.62 | L6: =-'Profit & Loss'!L12*assumption!$B$8 -> -2236.7147 | M6: =-'Profit & Loss'!M12*assumption!$B$8 -> -2393.0482 | N6: =-'Profit & Loss'!N12*assumption!$B$8 -> -2563.5955 | O6: =-'Profit & Loss'!O12*assumption!$B$8 -> -2743.3956 | P6: =-'Profit & Loss'!P12*assumption!$B$8 -> -2939.0677
A7: Net Cash Flow | B7: ='Data Sheet'!B85 -> -3.65 | C7: ='Data Sheet'!C85 -> 60.5 | D7: ='Data Sheet'!D85 -> -49.12 | E7: ='Data Sheet'!E85 -> 16.54 | F7: ='Data Sheet'!F85 -> 66.2 | G7: ='Data Sheet'!G85 -> -32.13 | H7: ='Data Sheet'!H85 -> -9.16 | I7: ='Data Sheet'!I85 -> 219.29 | ... K7: ='Data Sheet'!K85 -> 87.6 | L7: =L4+L5+L6 -> 0.09 | M7: =M4+M5+M6 -> 0 | N7: =N4+N5+N6 -> 0 | O7: =O4+O5+O6 -> 0 | P7: =P4+P5+P6 -> 0

Sheet assumption
A1: Revenue growth % | B1: =('Profit & Loss'!K4/'Profit & Loss'!E4)^(1/7)-1 -> 0.074259243
A2: Operating margin (OPM) % | B2: ='Profit & Loss'!K6/'Profit & Loss'!K4 -> 0.18350121
A3: Effective tax rate % | B3: 0.24
A4: Depreciation as % of Fixed Assets + CWIP | B4: 0.11
A5: Capex as % of Sales | B5: 0.03
A6: Interest rate on average borrowings % | B6: 0.09
A7: Working capital as % of Sales | B7: -0.03
A8: Dividend payout % | B8: 0.83

Sheet Data Sheet
A1: COMPANY NAME | B1: BRITANNIA INDUSTRIES LTD | E1: =IF(B2<>B3, "A NEW VERSION OF THE WORKSHEET IS AVAILABLE", "")
A2: LATEST VERSION | B2: 2.1 | E2: PLEASE DO NOT MAKE ANY CHANGES TO THIS SHEET
A3: CURRENT VERSION | B3: 2.1
A5: META
A6: Number of shares | B6: =IF(B9>0, B9/B8, 0) -> 24.08683
A7: Face Value | B7: 1
A8: Current Price | B8: 5558
A9: Market Capitalization | B9: 133874.6
A15: PROFIT & LOSS
A16: Report Date | B16: 42825 | C16: 43190 | D16: 43555 | E16: 43921 | F16: 44286 | G16: 44651 | H16: 45016 | I16: 45382 | J16: 45747 | K16: 46112
A17: Sales | B17: 9054.09 | C17: 9913.99 | D17: 11054.67 | E17: 11599.55 | F17: 13136.14 | G17: 14136.26 | H17: 16300.55 | I17: 16769.27 | J17: 17942.67 | K17: 19151.59
A18: Raw Material Cost | B18: 5642.88 | C18: 6100.8 | D18: 6616.64 | E18: 6874.9 | F18: 7663.22 | G18: 8835.56 | H18: 9663.83 | I18: 9488.37 | J18: 10668.8 | K18: 11155.25
A19: Change in Inventory | B19: 54.2 | C19: -6.3 | D19: 55.18 | E19: -52.57 | F19: 37.12 | G19: 75.26 | H19: 72.53 | I19: -3.66 | J19: 64.75 | K19: 22.37
A20: Power and Fuel | B20: 104.28 | C20: 128.83 | D20: 175.17 | E20: 177.7 | F20: 182.29 | G20: 217.68 | H20: 272.2 | I20: 327.25 | J20: 357.98 | K20: 342.87
A21: Other Mfr. Exp | B21: 509.93 | C21: 487.59 | D21: 621.32 | E21: 610.68 | F21: 672.21 | G21: 752.29 | H21: 893.75 | I21: 876.12 | J21: 954.03 | K21: 920.68
A22: Employee Cost | B22: 352.61 | C22: 401.6 | D22: 441.82 | E22: 486.69 | F22: 527.38 | G22: 542.26 | H22: 658.38 | I22: 708.7 | J22: 704.59 | K22: 823.8
A23: Selling and admin | B23: 915.01 | C23: 953.48 | D23: 1107.49 | E23: 1125.23 | F23: 1163.82 | G23: 1187.32 | H23: 1473.86 | I23: 1525.52 | J23: 1360 | K23: 1575.23
A24: Other Expenses | B24: 305.4 | C24: 333.92 | D24: 414.96 | E24: 428.6 | F24: 455.05 | G24: 475.1 | H24: 580.15 | I24: 673 | J24: 785.61 | K24: 841.79
A25: Other Income | B25: 150.54 | C25: 166.37 | D25: 206.45 | E25: 262.83 | F25: 313.07 | G25: 221.85 | H25: 596.87 | I25: 211.28 | J25: 202.3 | K25: 224.03
A26: Depreciation | B26: 119.27 | C26: 142.07 | D26: 161.88 | E26: 184.81 | F26: 197.85 | G26: 200.54 | H26: 225.91 | I26: 300.46 | J26: 313.34 | K26: 336.83
A27: Interest | B27: 5.45 | C27: 7.59 | D27: 9.09 | E27: 76.9 | F27: 110.9 | G27: 144.29 | H27: 169.1 | I27: 164 | J27: 138.8 | K27: 112.76
... A31: Dividend Amount | B31: 264 | C31: 300.12 | D31: 360.45 | E31: 841.75 | F31: 3794.18 | G31: 1361.08 | H31: 1734.48 | I31: 1770.62 | J31: 1806.75 | K31: 2180.14
A40: Quarters
A41: Report Date | B41: 45382 | C41: 45473 | D41: 45565 | E41: 45657 | F41: 45747 | G41: 45838 | H41: 45930 | I41: 46022 | J41: 46112 | K41: 46203
A42: Sales | B42: 4069.36 | C42: 4250.29 | D42: 4667.57 | E42: 4592.61 | F42: 4432.19 | G42: 4622.22 | H42: 4840.63 | I42: 4969.82 | J42: 4718.92 | K42: 4999.97
A43: Expenses | B43: 3285.71 | C43: 3497.28 | D43: 3887.56 | E43: 3749.75 | F43: 3631.67 | G43: 3870.02 | H43: 3889.39 | I43: 3992.49 | J43: 3885.35 | K43: 4161.65
A44: Other Income | B44: 57.34 | C44: 30.97 | D44: 45.85 | E44: 62.46 | F44: 63.02 | G44: 57.01 | H44: 52.11 | I44: 59.46 | J44: 55.45 | K44: 61.41
A45: Depreciation | B45: 79.93 | C45: 73.93 | D45: 76.07 | E45: 82.38 | F45: 80.96 | G45: 82.04 | H45: 85.05 | I45: 84.51 | J45: 85.23 | K45: 79.51
A46: Interest | B46: 26.44 | C46: 28.95 | D46: 34.64 | E46: 44.56 | F46: 30.65 | G46: 26.15 | H46: 34.68 | I46: 33.25 | J46: 18.68 | K46: 22.87
A47: Profit before tax | B47: 734.62 | C47: 681.1 | D47: 715.15 | E47: 778.38 | F47: 751.93 | G47: 701.02 | H47: 883.62 | I47: 919.03 | J47: 785.11 | K47: 797.35
A48: Tax | B48: 198.01 | C48: 176.22 | D48: 183.6 | E48: 196.08 | F48: 192.8 | G48: 180.89 | H48: 228.56 | I48: 236.89 | J48: 105.43 | K48: 203.97
A49: Net profit | B49: 538.28 | C49: 505.64 | D49: 531.45 | E49: 581.69 | F49: 559.95 | G49: 520.72 | H49: 654.47 | I49: 679.96 | J49: 678.34 | K49: 591.35
A50: Operating Profit | B50: 783.65 | C50: 753.01 | D50: 780.01 | E50: 842.86 | F50: 800.52 | G50: 752.2 | H50: 951.24 | I50: 977.33 | J50: 833.57 | K50: 838.32
A55: BALANCE SHEET
A56: Report Date | B56: 42825 | C56: 43190 | D56: 43555 | E56: 43921 | F56: 44286 | G56: 44651 | H56: 45016 | I56: 45382 | J56: 45747 | K56: 46112
A57: Equity Share Capital | B57: 24 | C57: 24.01 | D57: 24.03 | E57: 24.05 | F57: 24.09 | G57: 24.09 | H57: 24.09 | I57: 24.09 | J57: 24.09 | K57: 24.09
A58: Reserves | B58: 2672.42 | C58: 3382.22 | D58: 4229.22 | E58: 4378.78 | F58: 3523.57 | G58: 2534.01 | H58: 3510.18 | I58: 3917.43 | J58: 4331.63 | K58: 5082.47
A59: Borrowings | B59: 124.56 | C59: 200.7 | D59: 156.02 | E59: 1537.59 | F59: 2106.94 | G59: 2481.2 | H59: 2997.37 | I59: 2064.96 | J59: 1246.51 | K59: 1380.28
A60: Other Liabilities | B60: 1287.82 | C60: 1580.99 | D60: 1828.68 | E60: 1889.12 | F60: 2345.49 | G60: 2487.3 | H60: 2819.21 | I60: 3065.02 | J60: 3234.52 | K60: 3243.48
A61: Total | B61: 4108.8 | C61: 5187.92 | D61: 6237.95 | E61: 7829.54 | F61: 8000.09 | G61: 7526.6 | H61: 9350.85 | I61: 9071.5 | J61: 8836.75 | K61: 9730.32
...
